Workbook

Sheet Sales Data
A1: Order ID | B1: Order Date | C1: Customer | D1: Region | E1: Salesperson | F1: Customer Segment | G1: Product | H1: Category | I1: Quantity | J1: Unit Price | K1: Discount % | L1: Sales | M1: Cost | N1: Profit | O1: Payment Method
A2: ORD-10059 | B2: 45658 | C2: Vertex Enterprises | D2: West | E2: Aarav | F2: Small Business | G2: Keyboard | H2: Accessories | I2: 5 | J2: 2368 | K2: 0.05 | L2: 11248 | M2: 7930.93 | N2: 3317.07 | O2: Cash
A3: ORD-10069 | B3: 45658 | C3: BrightEdge Pvt Ltd | D3: West | E3: Vikram | F3: Consumer | G3: Keyboard | H3: Accessories | I3: 5 | J3: 2553 | K3: 0.05 | L3: 12126.75 | M3: 9068.07 | N3: 3058.68 | O3: Credit Card | R3: =MIN(I2:I501) -> 1
A4: ORD-10118 | B4: 45661 | C4: NextGen Systems | D4: South | E4: Ishita | F4: Corporate | G4: Webcam | H4: Accessories | I4: 2 | J4: 4860 | K4: 0.1 | L4: 8748 | M4: 6563.63 | N4: 2184.37 | O4: Credit Card | R4: =MAX(I2:I501) -> 8
A5: ORD-10098 | B5: 45662 | C5: Sunrise Associates | D5: West | E5: Meera | F5: Consumer | G5: Webcam | H5: Accessories | I5: 1 | J5: 4142 | K5: 0.1 | L5: 3727.8 | M5: 2547.36 | N5: 1180.44 | O5: Cash | R5: =MIN(L2:L501) -> 938.4
A6: ORD-10350 | B6: 45663 | C6: MetroMart | D6: North | E6: Diya | F6: Consumer | G6: Office Chair | H6: Furniture | I6: 4 | J6: 10255 | K6: 0.1 | L6: 36918 | M6: 23263.5 | N6: 13654.5 | O6: Bank Transfer | R6: =MIN(M2:M501) -> 671.84
A7: ORD-10114 | B7: 45664 | C7: GreenLeaf Traders | D7: West | E7: Rohan | F7: Small Business | G7: Webcam | H7: Accessories | I7: 7 | J7: 4712 | K7: 0.15 | L7: 28036.4 | M7: 17579.13 | N7: 10457.27 | O7: Credit Card | R7: =MIN(N2:N501) -> 181.19
A8: ORD-10440 | B8: 45664 | C8: Vertex Enterprises | D8: East | E8: Kabir | F8: Corporate | G8: Office Chair | H8: Furniture | I8: 8 | J8: 9263 | K8: 0.15 | L8: 62988.4 | M8: 50051.11 | N8: 12937.29 | O8: Credit Card
A9: ORD-10152 | B9: 45664 | C9: BluePeak Retail | D9: South | E9: Diya | F9: Small Business | G9: Laptop | H9: Electronics | I9: 6 | J9: 63333 | K9: 0.15 | L9: 322998.3 | M9: 211742.16 | N9: 111256.14 | O9: Credit Card
A10: ORD-10226 | B10: 45665 | C10: GreenLeaf Traders | D10: West | E10: Aarav | F10: Corporate | G10: Office Chair | H10: Furniture | I10: 1 | J10: 9967 | K10: 0.1 | L10: 8970.3 | M10: 6965.16 | N10: 2005.14 | O10: Bank Transfer
A11: ORD-10055 | B11: 45666 | C11: Sunrise Associates | D11: West | E11: Diya | F11: Corporate | G11: Webcam | H11: Accessories | I11: 2 | J11: 4606 | K11: 0 | L11: 9212 | M11: 5697.65 | N11: 3514.35 | O11: Credit Card
A12: ORD-10140 | B12: 45666 | C12: BrightEdge Pvt Ltd | D12: South | E12: Ananya | F12: Corporate | G12: Keyboard | H12: Accessories | I12: 4 | J12: 2747 | K12: 0 | L12: 10988 | M12: 7550.66 | N12: 3437.34 | O12: Debit Card
A13: ORD-10176 | B13: 45667 | C13: DigitalHub | D13: North | E13: Aarav | F13: Corporate | G13: Keyboard | H13: Accessories | I13: 6 | J13: 2334 | K13: 0.1 | L13: 12603.6 | M13: 8496.6 | N13: 4107 | O13: Bank Transfer
A14: ORD-10238 | B14: 45667 | C14: Sunrise Associates | D14: North | E14: Meera | F14: Small Business | G14: Headset | H14: Accessories | I14: 8 | J14: 3720 | K14: 0.1 | L14: 26784 | M14: 20123.74 | N14: 6660.26 | O14: Credit Card
A15: ORD-10407 | B15: 45668 | C15: DigitalHub | D15: West | E15: Ishita | F15: Consumer | G15: Tablet | H15: Electronics | I15: 7 | J15: 26564 | K15: 0.05 | L15: 176650.6 | M15: 119035.7 | N15: 57614.9 | O15: Cash
A16: ORD-10167 | B16: 45669 | C16: BluePeak Retail | D16: South | E16: Meera | F16: Corporate | G16: Tablet | H16: Electronics | I16: 4 | J16: 26093 | K16: 0.15 | L16: 88716.2 | M16: 57508.24 | N16: 31207.96 | O16: Cash
A17: ORD-10126 | B17: 45669 | C17: CloudNine Services | D17: North | E17: Vikram | F17: Corporate | G17: Keyboard | H17: Accessories | I17: 5 | J17: 2295 | K17: 0.15 | L17: 9753.75 | M17: 6145.84 | N17: 3607.91 | O17: Bank Transfer
A18: ORD-10379 | B18: 45669 | C18: PrimeOffice Supplies | D18: North | E18: Meera | F18: Small Business | G18: Headset | H18: Accessories | I18: 3 | J18: 3283 | K18: 0.05 | L18: 9356.55 | M18: 7538.56 | N18: 1817.99 | O18: Cash
A19: ORD-10045 | B19: 45673 | C19: MetroMart | D19: West | E19: Ishita | F19: Small Business | G19: Office Chair | H19: Furniture | I19: 8 | J19: 9770 | K19: 0 | L19: 78160 | M19: 56968.53 | N19: 21191.47 | O19: Debit Card
... A501: ORD-10451 | B501: 46022 | C501: CloudNine Services | D501: South | E501: Vikram | F501: Small Business | G501: Laptop | H501: Electronics | I501: 1 | J501: 60781 | K501: 0.1 | L501: 54702.9 | M501: 39793.58 | N501: 14909.32 | O501: Bank Transfer

Sheet Analysis
A1: Total Sales | B1: =SUM('Sales Data'!L:L) -> 35864388
A2: Total Cost | B2: =SUM('Sales Data'!M:M) -> 25665000
A3: Total Profit | B3: =SUM('Sales Data'!N:N) -> 10199388
A4: Total Orders | B4: =COUNTA('Sales Data'!A:A)-1 -> 500
A5: Total Quantity Sold | B5: =SUM('Sales Data'!I:I) -> 2220
A6: Average Order Value | B6: =B2/B5 -> 11560.811
A7: Profit Margin % | B7: =B3/B1 -> 0.28438762
A10: Region | B10: Total Sales
A11: North | B11: =SUMIF('Sales Data'!D:D,A11,'Sales Data'!L:L) -> 9957463.5
A12: South | B12: =SUMIF('Sales Data'!D:D,A12,'Sales Data'!L:L) -> 8994165.8
A13: East | B13: =SUMIF('Sales Data'!D:D,A13,'Sales Data'!L:L) -> 9184415.7
A14: West | B14: =SUMIF('Sales Data'!D:D,A14,'Sales Data'!L:L) -> 7728343.1
A16: Product | B16: Total Sales
A17: Laptop | B17: =SUMIF('Sales Data'!G:G,A17,'Sales Data'!L:L) -> 16451576
A18: Monitor | B18: =SUMIF('Sales Data'!G:G,A18,'Sales Data'!L:L) -> 3683965.8
A19: Keyboard | B19: =SUMIF('Sales Data'!G:G,A19,'Sales Data'!L:L) -> 470972.45
A20: Mouse | B20: =SUMIF('Sales Data'!G:G,A20,'Sales Data'!L:L) -> 210985.3
A21: Headset | B21: =SUMIF('Sales Data'!G:G,A21,'Sales Data'!L:L) -> 744771.3
A22: Printer | B22: =SUMIF('Sales Data'!G:G,A22,'Sales Data'!L:L) -> 2159941.5
A23: Tablet | B23: =SUMIF('Sales Data'!G:G,A23,'Sales Data'!L:L) -> 6637203
A24: Office Chair | B24: =SUMIF('Sales Data'!G:G,A24,'Sales Data'!L:L) -> 2315081.3
A25: Desk | B25: =SUMIF('Sales Data'!G:G,A25,'Sales Data'!L:L) -> 2368240.1
A26: Webcam | B26: =SUMIF('Sales Data'!G:G,A26,'Sales Data'!L:L) -> 821651.65
A28: Month | B28: Total Sales
A29: January | B29: =SUMIFS('Sales Data'!L:L,'Sales Data'!B:B,">="&DATE(2025,ROW()-28,1),'Sales Data'!B:B,"<"&EDATE(DATE(2025,ROW()-28,1),1)) -> 2685340
A30: February | B30: =SUMIFS('Sales Data'!L:L,'Sales Data'!B:B,">="&DATE(2025,ROW()-28,1),'Sales Data'!B:B,"<"&EDATE(DATE(2025,ROW()-28,1),1)) -> 2744014.1
A31: March | B31: =SUMIFS('Sales Data'!L:L,'Sales Data'!B:B,">="&DATE(2025,ROW()-28,1),'Sales Data'!B:B,"<"&EDATE(DATE(2025,ROW()-28,1),1)) -> 2017815.7
A32: April | B32: =SUMIFS('Sales Data'!L:L,'Sales Data'!B:B,">="&DATE(2025,ROW()-28,1),'Sales Data'!B:B,"<"&EDATE(DATE(2025,ROW()-28,1),1)) -> 4682589
A33: May | B33: =SUMIFS('Sales Data'!L:L,'Sales Data'!B:B,">="&DATE(2025,ROW()-28,1),'Sales Data'!B:B,"<"&EDATE(DATE(2025,ROW()-28,1),1)) -> 3276481.9
A34: June | B34: =SUMIFS('Sales Data'!L:L,'Sales Data'!B:B,">="&DATE(2025,ROW()-28,1),'Sales Data'!B:B,"<"&EDATE(DATE(2025,ROW()-28,1),1)) -> 2174488.2
A35: July | B35: =SUMIFS('Sales Data'!L:L,'Sales Data'!B:B,">="&DATE(2025,ROW()-28,1),'Sales Data'!B:B,"<"&EDATE(DATE(2025,ROW()-28,1),1)) -> 3098100.8
A36: August | B36: =SUMIFS('Sales Data'!L:L,'Sales Data'!B:B,">="&DATE(2025,ROW()-28,1),'Sales Data'!B:B,"<"&EDATE(DATE(2025,ROW()-28,1),1)) -> 2921973.6
A37: September | B37: =SUMIFS('Sales Data'!L:L,'Sales Data'!B:B,">="&DATE(2025,ROW()-28,1),'Sales Data'!B:B,"<"&EDATE(DATE(2025,ROW()-28,1),1)) -> 2283264.1
A38: October | B38: =SUMIFS('Sales Data'!L:L,'Sales Data'!B:B,">="&DATE(2025,ROW()-28,1),'Sales Data'!B:B,"<"&EDATE(DATE(2025,ROW()-28,1),1)) -> 2971438.8
A39: November | B39: =SUMIFS('Sales Data'!L:L,'Sales Data'!B:B,">="&DATE(2025,ROW()-28,1),'Sales Data'!B:B,"<"&EDATE(DATE(2025,ROW()-28,1),1)) -> 3242403.1
A40: December | B40: =SUMIFS('Sales Data'!L:L,'Sales Data'!B:B,">="&DATE(2025,ROW()-28,1),'Sales Data'!B:B,"<"&EDATE(DATE(2025,ROW()-28,1),1)) -> 3766478.6
A42: Customer Segment | B42: Total Sales
A43: Corporate | B43: =SUMIF('Sales Data'!F:F,A43,'Sales Data'!L:L) -> 11132157
A44: Small Business | B44: =SUMIF('Sales Data'!F:F,A44,'Sales Data'!L:L) -> 12676095
A45: Consumer | B45: =SUMIF('Sales Data'!F:F,A45,'Sales Data'!L:L) -> 12056137
...

Sheet Dashboard
A1: SALES PERFORMANCE DASHBOARD
A2: Sales Analysis | 2025
B4: Total Sales | D4: Total Cost | F4: Total Profit | H4: Total Orders | J4: Quantity Sold | L4: Profit Margin
B5: =Analysis!B1 -> 35864388 | D5: =Analysis!B2 -> 25665000 | F5: =Analysis!B3 -> 10199388 | H5: =Analysis!B4 -> 500 | J5: =Analysis!B5 -> 2220 | L5: =Analysis!B7 -> 0.28438762
H36: KEY INSIGHTS
H37: North generated the highest regional sales.
H38: Laptop is the top-selling product and highest profit contributor.
H39: April recorded the highest monthly sales.
H40: Small Business generated the highest sales among customer segments.
